<?xml version="1.0" ?>
<robot name="balancio" xmlns:xacro="http://www.ros.org/wiki/xacro">

  <material name="black">
    <color rgba="0.0 0.0 0.0 0.8"/>
  </material>
  <material name="blue">
    <color rgba="0.203125 0.23828125 0.28515625 0.8"/>
  </material>
  <material name="green">
    <color rgba="0.0 0.8 0.0 0.8"/>
  </material>
  <material name="grey">
    <color rgba="0.8 0.8 0.8 1.0"/>
  </material>
  <material name="orange">
    <color rgba="1.0 0.423529411765 0.0392156862745 1.0"/>
  </material>
  <material name="brown">
    <color rgba="0.870588235294 0.811764705882 0.764705882353 1.0"/>
  </material>
  <material name="red">
    <color rgba="0.80078125 0.12890625 0.1328125 1.0"/>
  </material>
  <material name="white">
    <color rgba="1.0 1.0 1.0 1.0"/>
  </material>


 <!-- Base -->
	<!-- <link name="dummy_link"/>

  <joint name="base_joint" type="fixed">
    <origin rpy="0 0 0" xyz="0 0 0"/>
		<child link="link_chassis"/>
    <parent link="dummy_link"/>
  </joint> -->

<!-- Unidades: Tiempo: 10*Segundo  -  Distancia: Decimetro  - Masa: 40*Kg -->

  <link name="link_chassis">
    <!-- pose and inertial -->
    <pose>0 0 0 0 0 0</pose>
    <inertial>
      <mass value="10.36"/>
      <origin rpy="0 0 0" xyz="1.5e-2 0 0.642"/>
      <inertia ixx="4.688" ixy="9.404e-5" ixz="1.335e-1" iyy="4.364" iyz="-1.6e-3" izz="9.11e-1"/>
    </inertial>
    <!-- body -->
    <collision name="collision_chassis">
      <origin rpy="0 0 0" xyz="0 0 0.2"/>
      <geometry>
        <box size="0.1 0.6 1.5"/>
        <!-- <mesh filename="package://Code/Simulation/stl/Body.stl" scale="10 10 10"/> -->
      </geometry>
    </collision>
    <visual>
      <origin rpy="0 0 0" xyz="0 0 0"/>
      <geometry>
        <!-- <box size="0.1 0.6 1.5"/> -->
        <mesh filename="package://Code/Simulation/stl/Body.stl" scale="10 10 10"/>
      </geometry>
      <material name="grey"/>
    </visual>
  </link>


<!--Gearbox and Wheels -->
<!-- Left -->

  <joint name="joint_left_gb" type="continuous">
    <origin rpy="0 0 0" xyz="0 0.316 -0.422"/>
    <child link="link_left_gb"/>
    <parent link="link_chassis"/>
    <axis rpy="0 0 0" xyz="0 1 0"/>
    <!-- <limit effort="0.8" velocity="30"/> -->
    <dynamics damping="0" friction="0"/>  <!-- Friction implemented in pybullet-->
  </joint>

  <link name="link_left_gb">
    <inertial>
      <mass value="0.56"/>
      <origin rpy="0 0 0" xyz="0 0 0"/>
      <inertia ixx="0.02544" ixy="0" ixz="0" iyy="0.04484" iyz="0" izz="0.02544"/>
    </inertial>
    <collision name="link_left_gb_collision">
      <origin rpy="0 1.5707 1.5707" xyz="0 0.05 0"/>
      <geometry>
        <cylinder length="0.1" radius="0.2"/>
      </geometry>
    </collision>
    <visual name="link_left_gb_visual">
      <origin rpy="0 1.5707 1.5707" xyz="0 0.05 0"/>
      <geometry>
        <cylinder length="0.1" radius="0.2"/>
      </geometry>
      <material name="green"/>
    </visual>
  </link>

  <joint name="joint_left_wheel" type="revolute">
    <limit lower="-0.03055" upper="0.03055" />
    <origin rpy="0 0 0" xyz="0 0 0"/>
    <child link="link_left_wheel"/>
    <parent link="link_left_gb"/>
    <axis rpy="0 0 0" xyz="0 1 0"/>
    <!-- <limit effort="0.8" velocity="30"/> -->
    <dynamics damping="0" friction="0"/>  <!-- Friction implemented in pybullet-->
  </joint>

  <link name="link_left_wheel">
    <inertial>
      <mass value="0.6"/>
      <origin rpy="0 0 0" xyz="0 0.142 0"/>
      <inertia ixx="0.02544" ixy="0" ixz="0" iyy="0.04484" iyz="0" izz="0.02544"/>
    </inertial>
    <collision name="link_left_wheel_collision">
      <origin rpy="3.14159 0 1.5707" xyz="0 0 0"/>
      <geometry>
        <!-- <cylinder length="0.005" radius="0.02"/> -->
        <mesh filename="package://Code/Simulation/stl/Wheel.stl" scale="10 10 10"/>
      </geometry>
    </collision>
    <visual name="link_left_wheel_visual">
      <origin rpy="3.14159 0 1.5707" xyz="0 0 0"/>
      <geometry>
        <!-- <cylinder length="0.005" radius="0.02"/> -->
        <mesh filename="package://Code/Simulation/stl/Wheel.stl" scale="10 10 10"/>
      </geometry>
      <material name="blue"/>
    </visual>
  </link>


<!-- Right -->

  <joint name="joint_right_gb" type="continuous">
    <origin rpy="0 0 0" xyz="0 -0.316 -0.422"/>
    <child link="link_right_gb"/>
    <parent link="link_chassis"/>
    <axis rpy="0 0 0" xyz="0 1 0"/>
    <!-- <limit effort="0.8" velocity="30"/> -->
    <dynamics damping="0" friction="0"/>  <!-- Friction implemented in pybullet-->
  </joint>

  <link name="link_right_gb">
    <inertial>
      <mass value="0.56"/>
      <origin rpy="0 0 0" xyz="0 0 0"/>
      <inertia ixx="0.02544" ixy="0" ixz="0" iyy="0.04484" iyz="0" izz="0.02544"/>
    </inertial>
    <collision name="link_right_gb_collision">
      <origin rpy="0 1.5707 1.5707" xyz="0 -0.05 0"/>
      <geometry>
        <cylinder length="0.1" radius="0.2"/>
      </geometry>
    </collision>
    <visual name="link_right_gb_visual">
      <origin rpy="0 1.5707 1.5707" xyz="0 -0.05 0"/>
      <geometry>
        <cylinder length="0.1" radius="0.2"/>
      </geometry>
      <material name="green"/>
    </visual>
  </link>

  <joint name="joint_right_wheel" type="revolute">
    <limit lower="-0.03055" upper="0.03055" />
    <origin rpy="0 0 0" xyz="0 0 0"/>
    <child link="link_right_wheel"/>
    <parent link="link_right_gb"/>
    <axis rpy="0 0 0" xyz="0 1 0"/>
		<!-- <limit effort="0.8" velocity="30"/> -->
    <dynamics damping="0" friction="0"/>  <!-- Friction implemented in pybullet-->
  </joint>

  <link name="link_right_wheel">
    <inertial>
      <mass value="0.6"/>
      <origin rpy="0 0 0" xyz="0 -0.142 0"/>
      <inertia ixx="0.02544" ixy="0" ixz="0" iyy="0.04484" iyz="0" izz="0.02544"/>
    </inertial>
    <collision name="link_right_wheel_collision">
      <origin rpy="0 0 -1.5707" xyz="0 0 0"/>
      <geometry>
        <!-- <cylinder length="0.005" radius="0.02"/> -->
        <mesh filename="package://Code/Simulation/stl/Wheel.stl" scale="10 10 10"/>
      </geometry>
    </collision>
    <visual name="link_right_wheel_visual">
      <origin rpy="0 0 -1.5707" xyz="0 0 0"/>
      <geometry>
        <!-- <cylinder length="0.005" radius="0.02"/> -->
        <mesh filename="package://Code/Simulation/stl/Wheel.stl" scale="10 10 10"/>
      </geometry>
      <material name="blue"/>
    </visual>
  </link>

</robot>
