<?xml version="1.0" ?>
<robot name="balancio" xmlns:xacro="http://www.ros.org/wiki/xacro">

  <material name="black">
    <color rgba="0.0 0.0 0.0 0.8"/>
  </material>
  <material name="blue">
    <color rgba="0.203125 0.23828125 0.28515625 0.8"/>
  </material>
  <material name="green">
    <color rgba="0.0 0.8 0.0 0.8"/>
  </material>
  <material name="grey">
    <color rgba="0.8 0.8 0.8 1.0"/>
  </material>
  <material name="orange">
    <color rgba="1.0 0.423529411765 0.0392156862745 1.0"/>
  </material>
  <material name="brown">
    <color rgba="0.870588235294 0.811764705882 0.764705882353 1.0"/>
  </material>
  <material name="red">
    <color rgba="0.80078125 0.12890625 0.1328125 1.0"/>
  </material>
  <material name="white">
    <color rgba="1.0 1.0 1.0 1.0"/>
  </material>


 <!-- Base -->
	<!-- <link name="dummy_link"/>

  <joint name="base_joint" type="fixed">
    <origin rpy="0 0 0" xyz="0 0 0"/>
		<child link="link_chassis"/>
    <parent link="dummy_link"/>
  </joint> -->

  <link name="link_chassis">
    <!-- pose and inertial -->
    <pose>0 0 0 0 0 0</pose>
    <inertial>
      <mass value="0.259"/>
      <origin rpy="0 0 0" xyz="1.5e-3 0 0.0642"/>
      <inertia ixx="1.172e-3" ixy="2.351e-8" ixz="3.338e-5" iyy="1.091e-3" iyz="-4.0054e-7" izz="2.277e-4"/>
    </inertial>
    <!-- body -->
    <collision name="collision_chassis">
      <origin rpy="0 0 0" xyz="0 0 0"/>
      <geometry>
        <!-- <box size="0.01 0.07 0.3"/> -->
        <mesh filename="package://Code/Simulation/stl/Body.stl" scale="1 1 1"/>
      </geometry>
    </collision>
    <visual>
      <origin rpy="0 0 0" xyz="0 0 0"/>
      <geometry>
        <!-- <box size="0.01 0.07 0.3"/> -->
        <mesh filename="package://Code/Simulation/stl/Body.stl" scale="1 1 1"/>
      </geometry>
      <material name="grey"/>
    </visual>
  </link>


<!--Gearbox and Wheels -->
<!-- Left -->

  <joint name="joint_left_gb" type="continuous">
    <origin rpy="0 0 0" xyz="0 0.0316 -0.0422"/>
    <child link="link_left_gb"/>
    <parent link="link_chassis"/>
    <axis rpy="0 0 0" xyz="0 1 0"/>
    <!-- <limit effort="0.8" velocity="30"/> -->
    <dynamics damping="0" friction="0"/>  <!-- Friction implemented in pybullet-->
  </joint>

  <link name="link_left_gb">
    <inertial>
      <mass value="0.001"/>
      <origin rpy="0 0 0" xyz="0 0 0"/>
      <inertia ixx="1.272e-7" ixy="0" ixz="0" iyy="2.247e-7" iyz="0" izz="1.272e-7"/>
    </inertial>
    <collision name="link_left_gb_collision">
      <origin rpy="0 1.5707 1.5707" xyz="0 0.02 0"/>
      <geometry>
        <cylinder length="0.005" radius="0.01"/>
      </geometry>
    </collision>
    <visual name="link_left_gb_visual">
      <origin rpy="0 1.5707 1.5707" xyz="0 0.02 0"/>
      <geometry>
        <cylinder length="0.005" radius="0.01"/>
      </geometry>
      <material name="green"/>
    </visual>
  </link>

  <joint name="joint_left_wheel" type="revolute">
    <limit lower="-0.03055" upper="0.03055" />
    <origin rpy="0 0 0" xyz="0 0 0"/>
    <child link="link_left_wheel"/>
    <parent link="link_left_gb"/>
    <axis rpy="0 0 0" xyz="0 1 0"/>
    <!-- <limit effort="0.8" velocity="30"/> -->
    <dynamics damping="0" friction="0"/>  <!-- Friction implemented in pybullet-->
  </joint>

  <link name="link_left_wheel">
    <inertial>
      <mass value="0.029"/>
      <origin rpy="0 0 0" xyz="0 0.0142 0"/>
      <inertia ixx="1.272e-5" ixy="0" ixz="0" iyy="2.247e-5" iyz="0" izz="1.272e-5"/>
    </inertial>
    <collision name="link_left_wheel_collision">
      <origin rpy="3.14159 0 1.5707" xyz="0 0.1 0"/>
      <geometry>
        <!-- <cylinder length="0.005" radius="0.02"/> -->
        <mesh filename="package://Code/Simulation/stl/Wheel.stl" scale="1 1 1"/>
      </geometry>
    </collision>
    <visual name="link_left_wheel_visual">
      <origin rpy="3.14159 0 1.5707" xyz="0 0.1 0"/>
      <geometry>
        <!-- <cylinder length="0.005" radius="0.02"/> -->
        <mesh filename="package://Code/Simulation/stl/Wheel.stl" scale="1 1 1"/>
      </geometry>
      <material name="blue"/>
    </visual>
  </link>


<!-- Right -->

  <joint name="joint_right_gb" type="continuous">
    <origin rpy="0 0 0" xyz="0 -0.0316 -0.0422"/>
    <child link="link_right_gb"/>
    <parent link="link_chassis"/>
    <axis rpy="0 0 0" xyz="0 1 0"/>
    <!-- <limit effort="0.8" velocity="30"/> -->
    <dynamics damping="0" friction="0"/>  <!-- Friction implemented in pybullet-->
  </joint>

  <link name="link_right_gb">
    <inertial>
      <mass value="0.001"/>
      <origin rpy="0 0 0" xyz="0 0 0"/>
      <inertia ixx="1.272e-7" ixy="0" ixz="0" iyy="2.247e-7" iyz="0" izz="1.272e-7"/>
    </inertial>
    <collision name="link_right_gb_collision">
      <origin rpy="0 1.5707 1.5707" xyz="0 -0.02 0"/>
      <geometry>
        <cylinder length="0.005" radius="0.01"/>
      </geometry>
    </collision>
    <visual name="link_right_gb_visual">
      <origin rpy="0 1.5707 1.5707" xyz="0 -0.02 0"/>
      <geometry>
        <cylinder length="0.005" radius="0.01"/>
      </geometry>
      <material name="green"/>
    </visual>
  </link>

  <joint name="joint_right_wheel" type="revolute">
    <limit lower="-0.03055" upper="0.03055" />
    <origin rpy="0 0 0" xyz="0 0 0"/>
    <child link="link_right_wheel"/>
    <parent link="link_right_gb"/>
    <axis rpy="0 0 0" xyz="0 1 0"/>
		<!-- <limit effort="0.8" velocity="30"/> -->
    <dynamics damping="0" friction="0"/>  <!-- Friction implemented in pybullet-->
  </joint>

  <link name="link_right_wheel">
    <inertial>
      <mass value="0.029"/>
      <origin rpy="0 0 0" xyz="0 -0.0142 0"/>
      <inertia ixx="1.272e-5" ixy="0" ixz="0" iyy="2.247e-5" iyz="0" izz="1.272e-5"/>
    </inertial>
    <collision name="link_right_wheel_collision">
      <origin rpy="0 0 -1.5707" xyz="0 -0.1 0"/>
      <geometry>
        <!-- <cylinder length="0.005" radius="0.02"/> -->
        <mesh filename="package://Code/Simulation/stl/Wheel.stl" scale="1 1 1"/>
      </geometry>
    </collision>
    <visual name="link_right_wheel_visual">
      <origin rpy="0 0 -1.5707" xyz="0 -0.1 0"/>
      <geometry>
        <!-- <cylinder length="0.005" radius="0.02"/> -->
        <mesh filename="package://Code/Simulation/stl/Wheel.stl" scale="1 1 1"/>
      </geometry>
      <material name="blue"/>
    </visual>
  </link>

</robot>
